ERROR:    Exception in ASGI application
Traceback (most recent call last):
  File "/usr/local/lib/python3.11/site-packages/mysql/connector/network.py", line 547, in open_connection
    addrinfos = socket.getaddrinfo(self.server_host,
                ^^^^^^^^^^^^^^^^^^^^^^^^^^^^^^^^^^^^
  File "/usr/local/lib/python3.11/socket.py", line 962, in getaddrinfo
    for res in _socket.getaddrinfo(host, port, family, type, proto, flags):
               ^^^^^^^^^^^^^^^^^^^^^^^^^^^^^^^^^^^^^^^^^^^^^^^^^^^^^^^^^^^
socket.gaierror: [Errno -3] Temporary failure in name resolution

During handling of the above exception, another exception occurred:

INFO:     172.20.0.1:43830 - "GET /api/content HTTP/1.1" 500 Internal Server Error
Traceback (most recent call last):
  File "/usr/local/lib/python3.11/site-packages/uvicorn/protocols/http/httptools_impl.py", line 375, in run_asgi
    result = await app(self.scope, self.receive, self.send)
             ^^^^^^^^^^^^^^^^^^^^^^^^^^^^^^^^^^^^^^^^^^^^^^
  File "/usr/local/lib/python3.11/site-packages/uvicorn/middleware/proxy_headers.py", line 75, in __call__
    return await self.app(scope, receive, send)
           ^^^^^^^^^^^^^^^^^^^^^^^^^^^^^^^^^^^^
  File "/usr/local/lib/python3.11/site-packages/fastapi/applications.py", line 276, in __call__
    await super().__call__(scope, receive, send)
  File "/usr/local/lib/python3.11/site-packages/starlette/applications.py", line 122, in __call__
    await self.middleware_stack(scope, receive, send)
  File "/usr/local/lib/python3.11/site-packages/starlette/middleware/errors.py", line 184, in __call__
    raise exc
  File "/usr/local/lib/python3.11/site-packages/starlette/middleware/errors.py", line 162, in __call__
    await self.app(scope, receive, _send)
  File "/usr/local/lib/python3.11/site-packages/starlette/middleware/exceptions.py", line 79, in __call__
    raise exc
  File "/usr/local/lib/python3.11/site-packages/starlette/middleware/exceptions.py", line 68, in __call__
    await self.app(scope, receive, sender)
  File "/usr/local/lib/python3.11/site-packages/fastapi/middleware/asyncexitstack.py", line 21, in __call__
    raise e
  File "/usr/local/lib/python3.11/site-packages/fastapi/middleware/asyncexitstack.py", line 18, in __call__
    await self.app(scope, receive, send)
  File "/usr/local/lib/python3.11/site-packages/starlette/routing.py", line 718, in __call__
    await route.handle(scope, receive, send)
  File "/usr/local/lib/python3.11/site-packages/starlette/routing.py", line 276, in handle
    await self.app(scope, receive, send)
  File "/usr/local/lib/python3.11/site-packages/starlette/routing.py", line 66, in app
    response = await func(request)
               ^^^^^^^^^^^^^^^^^^^
  File "/usr/local/lib/python3.11/site-packages/fastapi/routing.py", line 237, in app
    raw_response = await run_endpoint_function(
                   ^^^^^^^^^^^^^^^^^^^^^^^^^^^^
  File "/usr/local/lib/python3.11/site-packages/fastapi/routing.py", line 163, in run_endpoint_function
    return await dependant.call(**values)
           ^^^^^^^^^^^^^^^^^^^^^^^^^^^^^^
  File "/code/app/api/main.py", line 32, in get_all_indicators
    all_indicators = await db.get_all_indicators()
                           ^^^^^^^^^^^^^^^^^^^^^^^
  File "/code/app/decorators/timer.py", line 11, in wrapper
    func(*args, **kwargs)
  File "/code/app/database/database.py", line 30, in get_all_indicators
    connection = connect()
                 ^^^^^^^^^
  File "/code/app/decorators/timer.py", line 11, in wrapper
    func(*args, **kwargs)
  File "/code/app/database/database.py", line 12, in connect
    connection = mysql.connector.connect( user="root", password="root", host="mysql", port="3308", database="dude_path_database")
                 ^^^^^^^^^^^^^^^^^^^^^^^^^^^^^^^^^^^^^^^^^^^^^^^^^^^^^^^^^^^^^^^^^^^^^^^^^^^^^^^^^^^^^^^^^^^^^^^^^^^^^^^^^^^^^^^^
  File "/usr/local/lib/python3.11/site-packages/mysql/connector/__init__.py", line 273, in connect
    return MySQLConnection(*args, **kwargs)
           ^^^^^^^^^^^^^^^^^^^^^^^^^^^^^^^^
  File "/usr/local/lib/python3.11/site-packages/mysql/connector/connection.py", line 114, in __init__
    self.connect(**kwargs)
  File "/usr/local/lib/python3.11/site-packages/mysql/connector/abstracts.py", line 1009, in connect
    self._open_connection()
  File "/usr/local/lib/python3.11/site-packages/mysql/connector/connection.py", line 418, in _open_connection
    self._socket.open_connection()
  File "/usr/local/lib/python3.11/site-packages/mysql/connector/network.py", line 565, in open_connection
    raise errors.InterfaceError(
mysql.connector.errors.InterfaceError: 2003: Can't connect to MySQL server on '%-.100s:%u' (%s) (Warning: %u format: a real number is required, not str)